<?xml version="1.0"?>
<robot xmlns:xacro="http://www.ros.org/wiki/xacro" name="my_robot">

    <material name="blue"> <color rgba="0 0 1 1"/> </material>
    <material name="grey"> <color rgba="0.5 0.5 0.5 1"/> </material>
    <material name="red"> <color rgba="1 0 0 1"/> </material>

    <xacro:macro name="inertial_sphere" params="mass radius *origin">
        <inertial>
            <xacro:insert_block name="origin"/>
            <mass value="${mass}"/>
            <inertia ixx="${(2/5) * mass * (radius*radius)}" ixy="0.0" ixz="0.0"
                     iyy="${(2/5) * mass * (radius*radius)}" iyz="0.0"
                     izz="${(2/5) * mass * (radius*radius)}"/>
        </inertial>
    </xacro:macro>  

    <xacro:macro name="inertial_cylinder" params="mass length radius *origin">
        <inertial>
            <xacro:insert_block name="origin"/>
            <mass value="${mass}"/>
            <inertia ixx="${(1/12) * mass * (3*radius*radius + length*length)}" ixy="0.0" ixz="0.0"
                     iyy="${(1/12) * mass * (3*radius*radius + length*length)}" iyz="0.0"
                     izz="${(1/2) * mass * (radius*radius)}"/>
        </inertial>
    </xacro:macro>

    <xacro:macro name="inertial_box" params="mass x y z *origin">
        <inertial>
            <xacro:insert_block name="origin"/>
            <mass value="${mass}"/>
            <inertia ixx="${(1/12) * mass * (y*y + z*z)}" ixy="0.0" ixz="0.0"
                     iyy="${(1/12) * mass * (x*x + z*z)}" iyz="0.0"
                     izz="${(1/12) * mass * (x*x + y*y)}"/>
        </inertial>
    </xacro:macro>

    <link name="base_footprint"/>

    <joint name="base_footprint_joint" type="fixed">
        <parent link="base_footprint"/>
        <child link="base_link"/>
        <origin xyz="0 0 0.1" rpy="0 0 0"/>
    </joint>

    <link name="base_link">
        <visual>
            <geometry> <box size="0.6 0.4 0.2"/> </geometry>
            <material name="blue"/>
        </visual>
        <collision>
            <geometry> <box size="0.6 0.4 0.2"/> </geometry>
        </collision>
        <xacro:inertial_box mass="0.5" x="0.6" y="0.4" z="0.2">
            <origin xyz="0 0 0" rpy="0 0 0"/>
        </xacro:inertial_box>
    </link>

    <link name="left_wheel">
        <visual>
            <geometry> <cylinder radius="0.1" length="0.05"/> </geometry>
            <material name="grey"/>
        </visual>
        <collision>
            <geometry> <cylinder radius="0.1" length="0.05"/> </geometry>
        </collision>
        <xacro:inertial_cylinder mass="0.1" length="0.05" radius="0.1">
            <origin xyz="0 0 0" rpy="0 0 0"/>
        </xacro:inertial_cylinder>
    </link>

    <joint name="left_wheel_joint" type="continuous">
        <parent link="base_link"/>
        <child link="left_wheel"/>
        <origin xyz="-0.1 0.225 -0.1" rpy="-${pi/2} 0 0"/>
        <axis xyz="0 0 1"/>
    </joint>

    <link name="right_wheel">
        <visual>
            <geometry> <cylinder radius="0.1" length="0.05"/> </geometry>
            <material name="grey"/>
        </visual>
        <collision>
            <geometry> <cylinder radius="0.1" length="0.05"/> </geometry>
        </collision>
        <xacro:inertial_cylinder mass="0.1" length="0.05" radius="0.1">
            <origin xyz="0 0 0" rpy="0 0 0"/>
        </xacro:inertial_cylinder>
    </link>

    <joint name="right_wheel_joint" type="continuous">
        <parent link="base_link"/>
        <child link="right_wheel"/>
        <origin xyz="-0.1 -0.225 -0.1" rpy="${pi/2} 0 0"/>
        <axis xyz="0 0 -1"/>
    </joint>

    <link name="caster_wheel">
        <visual>
            <geometry> <sphere radius="0.05"/> </geometry>
            <material name="grey"/>
        </visual>
        <collision>
            <geometry> <sphere radius="0.05"/> </geometry>
        </collision>
        <xacro:inertial_sphere mass="0.1" radius="0.05">
            <origin xyz="0 0 0" rpy="0 0 0"/>
        </xacro:inertial_sphere>
    </link>

    <joint name="caster_wheel_joint" type="fixed">
        <parent link="base_link"/>
        <child link="caster_wheel"/>
        <origin xyz="0.2 0 -0.15" rpy="0 0 0"/>
    </joint>

    <link name="laser_frame">
        <visual>
            <geometry> <cylinder radius="0.05" length="0.04"/> </geometry>
            <material name="red"/>
        </visual>
        <collision>
            <geometry> <cylinder radius="0.05" length="0.04"/> </geometry>
        </collision>
        <xacro:inertial_cylinder mass="0.1" length="0.04" radius="0.05">
            <origin xyz="0 0 0" rpy="0 0 0"/>
        </xacro:inertial_cylinder>
    </link>

    <joint name="laser_joint" type="fixed">
        <parent link="base_link"/>
        <child link="laser_frame"/>
        <origin xyz="0.15 0 0.12" rpy="0 0 0"/>
    </joint>

    <gazebo>
        <plugin name="gz::sim::systems::DiffDrive" filename="gz-sim-diff-drive-system">
            <left_joint>left_wheel_joint</left_joint>
            <right_joint>right_wheel_joint</right_joint>
            <wheel_separation>0.45</wheel_separation>
            <wheel_radius>0.1</wheel_radius>
            
            <topic>cmd_vel</topic>
            
            <publish_odom>true</publish_odom>
            <publish_odom_tf>true</publish_odom_tf>
            <publish_wheel_tf>false</publish_wheel_tf>
            <use_frame_id_prefix>false</use_frame_id_prefix>
            <odometry_topic>odom</odometry_topic>
            <odometry_frame>odom</odometry_frame>
            <robot_base_frame>base_footprint</robot_base_frame>
        </plugin>

        <plugin name="gz::sim::systems::JointStatePublisher" filename="gz-sim-joint-state-publisher-system">
            <topic>joint_states</topic>
            <joint_name>left_wheel_joint</joint_name>
            <joint_name>right_wheel_joint</joint_name>
        </plugin>
    </gazebo>

    <gazebo reference="laser_frame">
        <sensor name="gpu_lidar" type="gpu_lidar">
            <pose>0 0 0 0 0 0</pose>
            <visualize>true</visualize>
            <update_rate>10</update_rate>
            <always_on>true</always_on>
            <lidar>
                <scan>
                    <horizontal>
                        <samples>360</samples>
                        <resolution>1</resolution>
                        <min_angle>-3.14</min_angle>
                        <max_angle>3.14</max_angle>
                    </horizontal>
                </scan>
                <range>
                    <min>0.10</min>
                    <max>12.0</max>
                </range>
            </lidar>
            <topic>scan</topic>
            <gz_frame_id>laser_frame</gz_frame_id>
        </sensor>
    </gazebo>

</robot>